#######################################################################
# +-----------------------------------------------------------------+ #
# |                            BO3 object                           | #
# +-----------------------------------------------------------------+ #
#######################################################################

# The descriptions in this file are accurate only for TerrainControl and OTG.
# For MCW and OTG+ these descriptions are only accurate if the BO3 is used as a CustomObject.
# MCW and OTG+ completely reimplemented CustomStructure, check the MCW/OTG+ documentation for more information.

# This is the config file of a custom object.
# If you add this object correctly to your BiomeConfigs, it will spawn in the world.

# This is the creator of this BO3 object
Author: Unknown

# A short description of this BO3 object
Description: This BO3 was converted from a schematic using OTGEdit. The author and description information of the schematic could not be found. If you know who the author of the schematic is then please add this information.

# The BO3 version, don't change this! It can be used by external applications to do a version check.
Version: 3

# The settings mode, WriteAll, WriteWithoutComments or WriteDisable. See WorldConfig.
SettingsMode: WriteDisable

#######################################################################
# +-----------------------------------------------------------------+ #
# |                          Main settings                          | #
# +-----------------------------------------------------------------+ #
#######################################################################

# This needs to be set to true to spawn the object in the Tree and Sapling resources.
Tree: true

# The frequency of the BO3 from 1 to 200. Tries this many times to spawn this BO3 when using the CustomObject(...) resource.
# Ignored by Tree(..), Sapling(..) and CustomStructure(..)
Frequency: 40

# The rarity of the BO3 from 0 to 100. Each spawn attempt has rarity% chance to succeed when using the CustomObject(...) resource.
# Ignored by Tree(..), Sapling(..) and CustomStructure(..)
Rarity: 100.0

# If you set this to true, the BO3 will be placed with a random rotation.
RotateRandomly: true

# The spawn height of the BO3 - randomY, highestBlock or highestSolidBlock.
SpawnHeight: highestSolidBlock

# The height limits for the BO3.
MinHeight: 0

MaxHeight: 256

# Objects can have other objects attached to it: branches. Branches can also
# have branches attached to it, which can also have branches, etc. This is the
# maximum branch depth for this objects.
MaxBranchDepth: 10

# When spawned with the UseWorld keyword, this BO3 should NOT spawn in the following biomes.
# If you writer.write the BO3 name directly in the BiomeConfigs, this will be ignored.
ExcludedBiomes: All

# To optimise this BO3 for faster loading times you can use Notepad++ to find/replace comments and abbreviate things.
# Notepad++ find/replace with regex:
# Find: ^[#;].* replace to nothing removes all lines starting with # 
# Find: ^\s*$ replace to nothing removes most empty lines 
# Notepad++ find/replace without regex:
# *Warning: This will only work for OTG 1.10.2 v21 / OTG 1.11.2 v6 or higher. B( is not recognised by lower versions.
# Find: Block( replace to B(

#######################################################################
# +-----------------------------------------------------------------+ #
# |                      Source block settings                      | #
# +-----------------------------------------------------------------+ #
#######################################################################

# The block(s) the BO3 should spawn in.
SourceBlocks: AIR, STATIONARY_WATER, FLOWING_WATER

# The maximum percentage of the BO3 that can be outside the SourceBlock.
# The BO3 won't be placed on a location with more blocks outside the SourceBlock than this percentage.
MaxPercentageOutsideSourceBlock: 0

# What to do when a block is about to be placed outside the SourceBlock? (dontPlace, placeAnyway)
OutsideSourceBlock: dontPlace

#######################################################################
# +-----------------------------------------------------------------+ #
# |                              Blocks                             | #
# +-----------------------------------------------------------------+ #
#######################################################################

# All the blocks used in the BO3 are listed here. Possible blocks:
# Block(x,y,z,id[.data][,nbtfile.nbt) or B(x,y,z,id[.data][,nbtfile.nbt)
# RandomBlock(x,y,z,id[:data][,nbtfile.nbt],chance[,id[:data][,nbtfile.nbt],chance[,...]])
# So RandomBlock(0,0,0,CHEST,chest.nbt,50,CHEST,anotherchest.nbt,100) will spawn a chest at
# the BO3 origin, and give it a 50% chance to have the contents of chest.nbt, or, if that
# fails, a 100% percent chance to have the contents of anotherchest.nbt.

Block(-3,20,8,18)
Block(-3,20,10,18)
Block(-3,21,9,18)
Block(-3,21,10,18)
Block(-2,18,9,18)
Block(-2,19,10,18)
Block(-2,21,8,18)
Block(-2,21,9,18)
Block(-2,22,6,18)
Block(-2,22,8,18)
Block(-2,24,6,18)
Block(-1,18,8,18)
Block(-1,18,9,18)
Block(-1,18,11,18)
Block(-1,18,12,18)
Block(-1,19,3,18)
Block(-1,19,4,18)
Block(-1,19,7,18)
Block(-1,19,8,18)
Block(-1,19,9,18)
Block(-1,19,10,18)
Block(-1,19,11,18)
Block(-1,19,12,18)
Block(-1,20,3,18)
Block(-1,20,7,18)
Block(-1,20,9,18)
Block(-1,20,10,18)
Block(-1,21,4,18)
Block(-1,21,5,18)
Block(-1,21,7,18)
Block(-1,21,8,18)
Block(-1,21,10,18)
Block(-1,22,5,18)
Block(-1,22,6,18)
Block(-1,22,7,18)
Block(-1,22,8,18)
Block(-1,22,9,18)
Block(-1,23,9,18)
Block(-1,23,10,18)
Block(-1,24,5,18)
Block(-1,25,7,18)
Block(-1,26,9,18)
Block(-1,27,11,18)
Block(-1,28,5,18)
Block(-1,29,8,18)
Block(-1,30,9,18)
Block(-1,31,9,18)
Block(-1,31,10,18)
Block(0,17,11,18)
Block(0,17,12,18)
Block(0,17,13,18)
Block(0,18,2,18)
Block(0,18,4,18)
Block(0,18,9,18)
Block(0,18,11,18)
Block(0,18,12,18)
Block(0,19,3,18)
Block(0,19,4,18)
Block(0,19,5,18)
Block(0,19,6,18)
Block(0,19,7,18)
Block(0,19,8,18)
Block(0,19,9,18)
Block(0,19,10,18)
Block(0,19,11,18)
Block(0,19,12,18)
Block(0,19,13,18)
Block(0,20,3,18)
Block(0,20,5,18)
Block(0,20,6,18)
Block(0,20,7,18)
Block(0,20,8,18)
Block(0,20,9,18)
Block(0,20,10,18)
Block(0,20,11,18)
Block(0,20,12,18)
Block(0,21,2,18)
Block(0,21,5,18)
Block(0,21,6,18)
Block(0,21,7,18)
Block(0,21,8,18)
Block(0,21,9,18)
Block(0,21,11,18)
Block(0,21,12,18)
Block(0,21,13,18)
Block(0,22,4,18)
Block(0,22,7,18)
Block(0,22,8,18)
Block(0,22,10,18)
Block(0,22,13,18)
Block(0,23,4,18)
Block(0,23,5,18)
Block(0,23,6,18)
Block(0,23,7,18)
Block(0,23,8,18)
Block(0,23,9,18)
Block(0,23,10,18)
Block(0,24,4,18)
Block(0,24,5,18)
Block(0,24,6,18)
Block(0,24,7,18)
Block(0,24,8,18)
Block(0,24,10,18)
Block(0,25,6,18)
Block(0,25,7,18)
Block(0,25,8,18)
Block(0,25,11,18)
Block(0,26,4,18)
Block(0,26,6,18)
Block(0,26,8,18)
Block(0,26,10,18)
Block(0,26,11,18)
Block(0,27,5,18)
Block(0,28,4,18)
Block(0,28,5,18)
Block(0,28,7,18)
Block(0,28,10,18)
Block(0,29,8,18)
Block(0,30,5,18)
Block(0,30,9,18)
Block(0,31,5,18)
Block(0,31,9,18)
Block(0,32,10,18)
Block(0,34,8,18)
Block(0,34,9,18)
Block(0,35,7,18)
Block(0,35,8,18)
Block(1,17,12,18)
Block(1,18,3,18)
Block(1,18,11,18)
Block(1,18,12,18)
Block(1,19,3,18)
Block(1,19,4,18)
Block(1,19,5,18)
Block(1,19,6,18)
Block(1,19,7,18)
Block(1,19,8,18)
Block(1,19,9,18)
Block(1,19,10,18)
Block(1,19,11,18)
Block(1,19,12,18)
Block(1,20,1,18)
Block(1,20,2,18)
Block(1,20,4,18)
Block(1,20,6,18)
Block(1,20,7,18)
Block(1,20,8,18)
Block(1,20,9,18)
Block(1,20,10,18)
Block(1,20,13,18)
Block(1,21,2,18)
Block(1,21,3,18)
Block(1,21,4,18)
Block(1,21,5,18)
Block(1,21,6,18)
Block(1,21,7,18)
Block(1,21,8,18)
Block(1,21,9,18)
Block(1,21,10,18)
Block(1,21,12,18)
Block(1,21,13,18)
Block(1,21,14,18)
Block(1,22,4,18)
Block(1,22,5,18)
Block(1,22,6,18)
Block(1,22,7,18)
Block(1,22,8,18)
Block(1,22,9,18)
Block(1,22,10,18)
Block(1,22,11,18)
Block(1,23,4,18)
Block(1,23,5,18)
Block(1,23,7,18)
Block(1,23,9,18)
Block(1,23,10,18)
Block(1,23,11,18)
Block(1,24,4,18)
Block(1,24,5,18)
Block(1,24,6,18)
Block(1,24,7,18)
Block(1,24,8,18)
Block(1,24,10,18)
Block(1,24,11,18)
Block(1,24,12,18)
Block(1,25,5,18)
Block(1,25,7,18)
Block(1,25,8,18)
Block(1,25,10,18)
Block(1,25,11,18)
Block(1,25,12,18)
Block(1,26,4,18)
Block(1,26,5,18)
Block(1,26,6,18)
Block(1,26,7,18)
Block(1,26,8,18)
Block(1,26,9,18)
Block(1,26,10,18)
Block(1,26,12,18)
Block(1,27,4,18)
Block(1,27,5,18)
Block(1,27,6,18)
Block(1,27,7,18)
Block(1,27,11,18)
Block(1,27,12,18)
Block(1,28,5,18)
Block(1,28,6,18)
Block(1,28,9,18)
Block(1,28,10,18)
Block(1,28,11,18)
Block(1,29,5,18)
Block(1,29,6,18)
Block(1,29,7,18)
Block(1,29,9,18)
Block(1,29,10,18)
Block(1,29,11,18)
Block(1,30,5,18)
Block(1,30,6,18)
Block(1,30,7,18)
Block(1,30,8,18)
Block(1,30,9,18)
Block(1,30,10,18)
Block(1,30,11,18)
Block(1,31,4,18)
Block(1,31,7,18)
Block(1,31,8,18)
Block(1,31,9,18)
Block(1,31,11,18)
Block(1,32,5,18)
Block(1,32,6,18)
Block(1,32,8,18)
Block(1,32,10,18)
Block(1,33,5,18)
Block(1,33,6,18)
Block(1,33,9,18)
Block(1,34,5,18)
Block(1,34,7,18)
Block(1,35,6,18)
Block(1,35,10,18)
Block(1,36,8,18)
Block(1,37,7,18)
Block(2,0,7,18)
Block(2,1,8,18)
Block(2,15,8,18)
Block(2,15,9,18)
Block(2,17,11,18)
Block(2,18,11,18)
Block(2,18,12,18)
Block(2,19,3,18)
Block(2,19,4,18)
Block(2,19,6,18)
Block(2,19,7,18)
Block(2,19,10,18)
Block(2,19,12,18)
Block(2,19,14,18)
Block(2,20,2,18)
Block(2,20,3,18)
Block(2,20,5,18)
Block(2,20,6,18)
Block(2,20,8,18)
Block(2,20,9,18)
Block(2,20,10,18)
Block(2,20,11,18)
Block(2,20,12,18)
Block(2,20,13,18)
Block(2,20,15,18)
Block(2,21,2,18)
Block(2,21,3,18)
Block(2,21,4,18)
Block(2,21,5,18)
Block(2,21,6,18)
Block(2,21,7,18)
Block(2,21,8,18)
Block(2,21,9,18)
Block(2,21,10,18)
Block(2,21,11,18)
Block(2,21,12,18)
Block(2,21,13,18)
Block(2,21,14,18)
Block(2,22,3,18)
Block(2,22,5,18)
Block(2,22,6,18)
Block(2,22,7,18)
Block(2,22,8,18)
Block(2,22,9,18)
Block(2,22,11,18)
Block(2,22,14,18)
Block(2,23,4,18)
Block(2,23,5,18)
Block(2,23,6,18)
Block(2,23,8,18)
Block(2,23,9,18)
Block(2,23,11,18)
Block(2,23,12,18)
Block(2,23,13,18)
Block(2,24,2,18)
Block(2,24,3,18)
Block(2,24,4,18)
Block(2,24,5,18)
Block(2,24,6,18)
Block(2,24,8,18)
Block(2,24,9,18)
Block(2,25,3,18)
Block(2,25,4,18)
Block(2,25,6,18)
Block(2,25,7,18)
Block(2,25,8,18)
Block(2,25,10,18)
Block(2,25,11,18)
Block(2,26,4,18)
Block(2,26,5,18)
Block(2,26,6,18)
Block(2,26,7,18)
Block(2,26,8,18)
Block(2,26,10,18)
Block(2,26,11,18)
Block(2,26,13,18)
Block(2,27,3,18)
Block(2,27,6,18)
Block(2,27,10,18)
Block(2,27,11,18)
Block(2,27,13,18)
Block(2,28,4,18)
Block(2,28,5,18)
Block(2,28,9,18)
Block(2,28,10,18)
Block(2,28,11,18)
Block(2,29,4,18)
Block(2,29,5,18)
Block(2,29,6,18)
Block(2,29,7,18)
Block(2,29,8,18)
Block(2,29,12,18)
Block(2,30,3,18)
Block(2,30,4,18)
Block(2,30,5,18)
Block(2,30,6,18)
Block(2,30,7,18)
Block(2,30,8,18)
Block(2,30,9,18)
Block(2,30,10,18)
Block(2,30,11,18)
Block(2,30,12,18)
Block(2,31,4,18)
Block(2,31,5,18)
Block(2,31,6,18)
Block(2,31,8,18)
Block(2,31,9,18)
Block(2,31,12,18)
Block(2,32,4,18)
Block(2,32,5,18)
Block(2,32,6,18)
Block(2,32,7,18)
Block(2,32,8,18)
Block(2,32,10,18)
Block(2,33,5,18)
Block(2,33,6,18)
Block(2,33,8,18)
Block(2,33,10,18)
Block(2,34,3,18)
Block(2,34,4,18)
Block(2,34,6,18)
Block(2,34,7,18)
Block(2,34,8,18)
Block(2,34,9,18)
Block(2,34,10,18)
Block(2,35,6,18)
Block(2,35,7,18)
Block(2,35,8,18)
Block(2,35,9,18)
Block(2,35,10,18)
Block(2,36,6,18)
Block(2,36,7,18)
Block(2,36,8,18)
Block(2,37,6,18)
Block(2,37,7,18)
Block(2,38,5,18)
Block(2,38,7,18)
Block(2,38,8,18)
Block(2,39,5,18)
Block(2,39,6,18)
Block(2,39,7,18)
Block(2,40,5,18)
Block(2,40,6,18)
Block(3,0,6,18)
Block(3,0,7,17:12)
Block(3,0,8,17:12)
Block(3,0,9,17:12)
Block(3,1,7,17:12)
Block(3,1,8,17:12)
Block(3,1,9,17:12)
Block(3,2,7,18)
Block(3,2,8,17:12)
Block(3,2,9,18)
Block(3,3,8,17:12)
Block(3,4,8,17:12)
Block(3,4,9,18)
Block(3,5,8,17:12)
Block(3,6,8,17:12)
Block(3,7,8,17:12)
Block(3,8,8,17:12)
Block(3,9,8,17:12)
Block(3,10,7,18)
Block(3,10,8,17:12)
Block(3,11,6,18)
Block(3,11,7,18)
Block(3,11,8,17:12)
Block(3,12,8,17:12)
Block(3,13,8,17:12)
Block(3,14,8,17)
Block(3,14,9,18)
Block(3,15,8,17)
Block(3,15,9,18)
Block(3,16,8,17)
Block(3,17,8,17)
Block(3,18,8,17)
Block(3,18,11,18)
Block(3,18,12,18)
Block(3,19,1,18)
Block(3,19,4,18)
Block(3,19,6,18)
Block(3,19,7,18)
Block(3,19,8,17)
Block(3,19,11,18)
Block(3,19,12,18)
Block(3,19,13,18)
Block(3,20,1,18)
Block(3,20,2,18)
Block(3,20,3,18)
Block(3,20,5,18)
Block(3,20,6,18)
Block(3,20,7,18)
Block(3,20,8,17:12)
Block(3,20,9,18)
Block(3,20,10,18)
Block(3,20,12,18)
Block(3,20,13,18)
Block(3,20,14,18)
Block(3,21,2,18)
Block(3,21,3,18)
Block(3,21,4,18)
Block(3,21,5,18)
Block(3,21,6,18)
Block(3,21,7,18)
Block(3,21,8,18)
Block(3,21,10,18)
Block(3,21,12,18)
Block(3,21,13,18)
Block(3,21,14,18)
Block(3,22,3,18)
Block(3,22,4,18)
Block(3,22,6,18)
Block(3,22,7,18)
Block(3,22,8,18)
Block(3,22,10,18)
Block(3,22,13,18)
Block(3,23,2,18)
Block(3,23,3,18)
Block(3,23,4,18)
Block(3,23,5,18)
Block(3,23,6,18)
Block(3,23,7,18)
Block(3,23,8,18)
Block(3,23,9,18)
Block(3,23,10,18)
Block(3,23,11,18)
Block(3,23,13,18)
Block(3,24,2,18)
Block(3,24,3,18)
Block(3,24,4,18)
Block(3,24,5,18)
Block(3,24,6,18)
Block(3,24,7,18)
Block(3,24,8,18)
Block(3,24,9,18)
Block(3,24,11,18)
Block(3,24,13,18)
Block(3,25,3,18)
Block(3,25,4,18)
Block(3,25,5,18)
Block(3,25,6,18)
Block(3,25,8,18)
Block(3,25,9,18)
Block(3,25,10,18)
Block(3,25,11,18)
Block(3,25,12,18)
Block(3,26,4,18)
Block(3,26,7,18)
Block(3,26,8,18)
Block(3,26,9,18)
Block(3,26,10,18)
Block(3,26,11,18)
Block(3,26,12,18)
Block(3,26,13,18)
Block(3,26,14,18)
Block(3,27,4,18)
Block(3,27,5,18)
Block(3,27,6,18)
Block(3,27,7,18)
Block(3,27,8,18)
Block(3,27,9,18)
Block(3,27,10,18)
Block(3,27,11,18)
Block(3,27,12,18)
Block(3,27,13,18)
Block(3,27,14,18)
Block(3,28,3,18)
Block(3,28,4,18)
Block(3,28,5,18)
Block(3,28,8,18)
Block(3,28,9,18)
Block(3,28,10,18)
Block(3,28,11,18)
Block(3,29,5,18)
Block(3,29,6,18)
Block(3,29,7,18)
Block(3,29,8,18)
Block(3,29,9,18)
Block(3,29,10,18)
Block(3,29,11,18)
Block(3,30,3,18)
Block(3,30,4,18)
Block(3,30,5,18)
Block(3,30,6,18)
Block(3,30,7,18)
Block(3,30,8,18)
Block(3,30,9,18)
Block(3,30,10,18)
Block(3,30,11,18)
Block(3,30,12,18)
Block(3,31,4,18)
Block(3,31,5,18)
Block(3,31,6,18)
Block(3,31,8,18)
Block(3,31,10,18)
Block(3,31,12,18)
Block(3,32,4,18)
Block(3,32,5,18)
Block(3,32,6,18)
Block(3,32,9,18)
Block(3,32,10,18)
Block(3,32,11,18)
Block(3,33,3,18)
Block(3,33,5,18)
Block(3,33,6,18)
Block(3,33,7,18)
Block(3,33,8,18)
Block(3,33,9,18)
Block(3,33,10,18)
Block(3,34,5,18)
Block(3,34,6,18)
Block(3,34,7,18)
Block(3,34,8,18)
Block(3,34,9,18)
Block(3,35,5,18)
Block(3,35,6,18)
Block(3,35,8,18)
Block(3,35,10,18)
Block(3,35,11,18)
Block(3,36,6,18)
Block(3,36,8,18)
Block(3,36,9,18)
Block(3,36,11,18)
Block(3,37,6,18)
Block(3,37,7,18)
Block(3,37,8,18)
Block(3,38,5,18)
Block(3,38,6,18)
Block(3,38,7,18)
Block(3,38,8,18)
Block(3,38,9,18)
Block(3,39,4,18)
Block(3,39,7,18)
Block(3,39,8,18)
Block(3,39,9,18)
Block(3,40,7,18)
Block(3,40,8,18)
Block(3,40,9,18)
Block(3,41,5,18)
Block(3,41,6,18)
Block(3,41,7,18)
Block(3,41,8,18)
Block(3,42,6,18)
Block(3,42,7,18)
Block(4,0,7,17:12)
Block(4,0,8,17:12)
Block(4,0,9,17:12)
Block(4,1,6,18)
Block(4,1,7,17:12)
Block(4,1,8,17:12)
Block(4,1,9,17:12)
Block(4,2,7,17:12)
Block(4,2,8,17:12)
Block(4,2,9,17:12)
Block(4,3,7,17:12)
Block(4,3,8,17:12)
Block(4,3,9,17:12)
Block(4,4,7,17:12)
Block(4,4,8,17:12)
Block(4,4,9,17:12)
Block(4,5,7,17:12)
Block(4,5,8,17:12)
Block(4,5,9,17:12)
Block(4,6,7,17:12)
Block(4,6,8,17:12)
Block(4,7,7,17:12)
Block(4,7,8,17:12)
Block(4,8,7,17:12)
Block(4,8,8,17:12)
Block(4,9,7,17:12)
Block(4,9,8,17:12)
Block(4,10,7,17:12)
Block(4,10,8,17:12)
Block(4,11,7,17:12)
Block(4,11,8,17:12)
Block(4,12,6,18)
Block(4,12,7,17:12)
Block(4,12,8,17:12)
Block(4,13,7,17:12)
Block(4,13,8,17:12)
Block(4,14,7,17:12)
Block(4,14,8,17:12)
Block(4,15,7,17:12)
Block(4,15,8,17:12)
Block(4,16,7,17:12)
Block(4,16,8,17:12)
Block(4,17,7,17:12)
Block(4,17,8,17:12)
Block(4,18,7,17:12)
Block(4,18,8,17:12)
Block(4,19,4,18)
Block(4,19,5,18)
Block(4,19,7,17:12)
Block(4,19,8,17:12)
Block(4,19,9,18)
Block(4,19,10,18)
Block(4,19,11,18)
Block(4,19,13,18)
Block(4,19,14,18)
Block(4,20,2,18)
Block(4,20,3,18)
Block(4,20,4,18)
Block(4,20,5,18)
Block(4,20,6,18)
Block(4,20,7,17:12)
Block(4,20,8,17:12)
Block(4,20,9,18)
Block(4,20,10,18)
Block(4,20,11,18)
Block(4,20,12,18)
Block(4,20,13,18)
Block(4,20,14,18)
Block(4,21,1,18)
Block(4,21,2,18)
Block(4,21,3,18)
Block(4,21,4,18)
Block(4,21,5,18)
Block(4,21,6,18)
Block(4,21,7,17:12)
Block(4,21,8,17:12)
Block(4,21,9,18)
Block(4,21,11,18)
Block(4,21,12,18)
Block(4,21,14,18)
Block(4,22,2,18)
Block(4,22,3,18)
Block(4,22,4,18)
Block(4,22,5,18)
Block(4,22,6,18)
Block(4,22,7,17:12)
Block(4,22,8,17:12)
Block(4,22,9,18)
Block(4,22,10,18)
Block(4,22,11,18)
Block(4,22,13,18)
Block(4,23,1,18)
Block(4,23,3,18)
Block(4,23,5,18)
Block(4,23,6,18)
Block(4,23,7,17:12)
Block(4,23,8,17:12)
Block(4,23,9,18)
Block(4,23,10,18)
Block(4,23,11,18)
Block(4,23,12,18)
Block(4,23,13,18)
Block(4,24,2,18)
Block(4,24,3,18)
Block(4,24,4,18)
Block(4,24,5,18)
Block(4,24,6,18)
Block(4,24,8,17:12)
Block(4,24,9,18)
Block(4,24,10,18)
Block(4,24,11,18)
Block(4,24,12,18)
Block(4,24,13,18)
Block(4,25,5,18)
Block(4,25,6,18)
Block(4,25,7,18)
Block(4,25,8,17:12)
Block(4,25,10,18)
Block(4,25,11,18)
Block(4,25,12,18)
Block(4,26,3,18)
Block(4,26,4,18)
Block(4,26,5,18)
Block(4,26,6,18)
Block(4,26,7,18)
Block(4,26,8,17:12)
Block(4,26,9,18)
Block(4,26,11,18)
Block(4,26,12,18)
Block(4,26,13,18)
Block(4,26,14,18)
Block(4,27,3,18)
Block(4,27,5,18)
Block(4,27,6,18)
Block(4,27,7,18)
Block(4,27,8,17:12)
Block(4,27,9,18)
Block(4,27,10,18)
Block(4,27,11,18)
Block(4,27,13,18)
Block(4,28,5,18)
Block(4,28,6,18)
Block(4,28,7,18)
Block(4,28,8,17:12)
Block(4,28,9,18)
Block(4,28,10,18)
Block(4,29,2,18)
Block(4,29,3,18)
Block(4,29,5,18)
Block(4,29,6,18)
Block(4,29,7,18)
Block(4,29,8,17:12)
Block(4,29,11,18)
Block(4,30,5,18)
Block(4,30,6,18)
Block(4,30,8,17:12)
Block(4,30,9,18)
Block(4,30,10,18)
Block(4,30,11,18)
Block(4,31,5,18)
Block(4,31,6,18)
Block(4,31,7,18)
Block(4,31,8,17:12)
Block(4,32,4,18)
Block(4,32,6,18)
Block(4,32,7,18)
Block(4,32,8,17:12)
Block(4,32,9,18)
Block(4,33,4,18)
Block(4,33,7,18)
Block(4,33,8,17:12)
Block(4,33,9,18)
Block(4,33,10,18)
Block(4,34,6,18)
Block(4,34,7,18)
Block(4,34,8,17:12)
Block(4,34,9,18)
Block(4,35,4,18)
Block(4,35,5,18)
Block(4,35,6,18)
Block(4,35,7,18)
Block(4,35,8,17:12)
Block(4,35,9,18)
Block(4,35,10,18)
Block(4,36,7,18)
Block(4,36,8,17:12)
Block(4,36,9,18)
Block(4,36,10,18)
Block(4,37,5,18)
Block(4,37,6,18)
Block(4,37,7,18)
Block(4,37,8,17:12)
Block(4,37,9,18)
Block(4,37,10,18)
Block(4,38,6,18)
Block(4,38,7,18)
Block(4,38,8,18)
Block(4,38,9,18)
Block(4,39,6,18)
Block(4,39,7,18)
Block(4,39,8,18)
Block(4,39,9,18)
Block(4,39,10,18)
Block(4,40,5,18)
Block(4,40,6,18)
Block(4,40,7,18)
Block(4,40,8,18)
Block(4,40,9,18)
Block(4,41,6,18)
Block(4,41,7,18)
Block(4,41,8,18)
Block(4,42,5,18)
Block(4,42,6,18)
Block(4,42,7,18)
Block(4,42,8,18)
Block(4,43,6,18)
Block(4,43,7,18)
Block(5,0,7,17:12)
Block(5,0,8,17:12)
Block(5,0,9,17:12)
Block(5,1,7,17:12)
Block(5,1,8,17:12)
Block(5,2,7,18)
Block(5,2,8,17:12)
Block(5,3,8,17:12)
Block(5,4,8,17:12)
Block(5,5,8,17:12)
Block(5,6,8,17:12)
Block(5,7,8,17:12)
Block(5,11,6,18)
Block(5,12,7,18)
Block(5,19,0,18)
Block(5,19,6,18)
Block(5,19,7,18)
Block(5,19,8,18)
Block(5,19,10,18)
Block(5,19,11,18)
Block(5,20,1,18)
Block(5,20,2,18)
Block(5,20,4,18)
Block(5,20,6,18)
Block(5,20,7,18)
Block(5,20,8,18)
Block(5,20,9,18)
Block(5,20,10,18)
Block(5,20,11,18)
Block(5,20,12,18)
Block(5,20,13,18)
Block(5,21,1,18)
Block(5,21,2,18)
Block(5,21,3,18)
Block(5,21,4,18)
Block(5,21,5,18)
Block(5,21,6,18)
Block(5,21,7,18)
Block(5,21,8,18)
Block(5,21,9,18)
Block(5,21,10,18)
Block(5,21,12,18)
Block(5,21,13,18)
Block(5,21,14,18)
Block(5,22,2,18)
Block(5,22,3,18)
Block(5,22,5,18)
Block(5,22,6,18)
Block(5,22,7,18)
Block(5,22,8,18)
Block(5,22,9,18)
Block(5,22,10,18)
Block(5,22,11,18)
Block(5,22,12,18)
Block(5,23,2,18)
Block(5,23,4,18)
Block(5,23,5,18)
Block(5,23,6,18)
Block(5,23,7,18)
Block(5,23,8,18)
Block(5,23,10,18)
Block(5,23,11,18)
Block(5,23,12,18)
Block(5,23,13,18)
Block(5,24,2,18)
Block(5,24,4,18)
Block(5,24,5,18)
Block(5,24,6,18)
Block(5,24,7,18)
Block(5,24,8,18)
Block(5,24,9,18)
Block(5,24,10,18)
Block(5,24,11,18)
Block(5,24,12,18)
Block(5,25,4,18)
Block(5,25,6,18)
Block(5,25,8,18)
Block(5,25,9,18)
Block(5,25,10,18)
Block(5,25,11,18)
Block(5,25,12,18)
Block(5,25,13,18)
Block(5,26,4,18)
Block(5,26,5,18)
Block(5,26,6,18)
Block(5,26,7,18)
Block(5,26,8,18)
Block(5,26,10,18)
Block(5,26,11,18)
Block(5,26,12,18)
Block(5,27,3,18)
Block(5,27,4,18)
Block(5,27,6,18)
Block(5,27,7,18)
Block(5,27,8,18)
Block(5,27,10,18)
Block(5,27,12,18)
Block(5,28,5,18)
Block(5,28,6,18)
Block(5,28,7,18)
Block(5,28,8,18)
Block(5,28,9,18)
Block(5,28,11,18)
Block(5,29,3,18)
Block(5,29,4,18)
Block(5,29,5,18)
Block(5,29,6,18)
Block(5,29,7,18)
Block(5,29,9,18)
Block(5,29,10,18)
Block(5,29,11,18)
Block(5,30,2,18)
Block(5,30,5,18)
Block(5,30,6,18)
Block(5,30,8,18)
Block(5,30,11,18)
Block(5,31,3,18)
Block(5,31,4,18)
Block(5,31,6,18)
Block(5,31,7,18)
Block(5,31,8,18)
Block(5,31,11,18)
Block(5,32,4,18)
Block(5,32,6,18)
Block(5,32,8,18)
Block(5,32,9,18)
Block(5,32,10,18)
Block(5,33,5,18)
Block(5,33,6,18)
Block(5,33,7,18)
Block(5,33,8,18)
Block(5,33,9,18)
Block(5,33,10,18)
Block(5,34,5,18)
Block(5,34,6,18)
Block(5,34,7,18)
Block(5,34,8,18)
Block(5,34,9,18)
Block(5,35,5,18)
Block(5,35,6,18)
Block(5,35,7,18)
Block(5,35,9,18)
Block(5,35,10,18)
Block(5,35,11,18)
Block(5,36,5,18)
Block(5,36,6,18)
Block(5,36,7,18)
Block(5,36,8,18)
Block(5,36,9,18)
Block(5,37,5,18)
Block(5,37,6,18)
Block(5,37,7,18)
Block(5,37,8,18)
Block(5,37,9,18)
Block(5,38,4,18)
Block(5,38,6,18)
Block(5,38,7,18)
Block(5,38,8,18)
Block(5,38,9,18)
Block(5,39,7,18)
Block(5,39,8,18)
Block(5,39,9,18)
Block(5,40,4,18)
Block(5,40,6,18)
Block(5,40,7,18)
Block(5,41,5,18)
Block(5,41,6,18)
Block(5,41,7,18)
Block(5,42,6,18)
Block(5,42,7,18)
Block(5,42,8,18)
Block(5,43,7,18)
Block(6,18,5,18)
Block(6,18,6,18)
Block(6,18,11,18)
Block(6,19,4,18)
Block(6,19,7,18)
Block(6,19,8,18)
Block(6,19,10,18)
Block(6,19,12,18)
Block(6,20,1,18)
Block(6,20,2,18)
Block(6,20,4,18)
Block(6,20,5,18)
Block(6,20,6,18)
Block(6,20,8,18)
Block(6,20,10,18)
Block(6,20,11,18)
Block(6,20,12,18)
Block(6,20,13,18)
Block(6,21,2,18)
Block(6,21,3,18)
Block(6,21,4,18)
Block(6,21,5,18)
Block(6,21,6,18)
Block(6,21,8,18)
Block(6,21,9,18)
Block(6,21,10,18)
Block(6,21,11,18)
Block(6,21,12,18)
Block(6,21,13,18)
Block(6,22,4,18)
Block(6,22,5,18)
Block(6,22,6,18)
Block(6,22,7,18)
Block(6,22,8,18)
Block(6,22,9,18)
Block(6,22,10,18)
Block(6,22,11,18)
Block(6,23,4,18)
Block(6,23,5,18)
Block(6,23,6,18)
Block(6,23,7,18)
Block(6,23,8,18)
Block(6,23,9,18)
Block(6,23,10,18)
Block(6,23,11,18)
Block(6,23,12,18)
Block(6,24,2,18)
Block(6,24,3,18)
Block(6,24,4,18)
Block(6,24,5,18)
Block(6,24,7,18)
Block(6,24,8,18)
Block(6,24,10,18)
Block(6,24,11,18)
Block(6,24,12,18)
Block(6,24,13,18)
Block(6,25,3,18)
Block(6,25,4,18)
Block(6,25,5,18)
Block(6,25,6,18)
Block(6,25,8,18)
Block(6,25,9,18)
Block(6,25,10,18)
Block(6,25,11,18)
Block(6,26,4,18)
Block(6,26,5,18)
Block(6,26,6,18)
Block(6,26,7,18)
Block(6,26,8,18)
Block(6,26,9,18)
Block(6,26,10,18)
Block(6,27,4,18)
Block(6,27,5,18)
Block(6,27,9,18)
Block(6,28,3,18)
Block(6,28,6,18)
Block(6,28,7,18)
Block(6,28,10,18)
Block(6,29,4,18)
Block(6,29,6,18)
Block(6,29,7,18)
Block(6,29,8,18)
Block(6,29,10,18)
Block(6,29,11,18)
Block(6,30,5,18)
Block(6,30,6,18)
Block(6,30,8,18)
Block(6,31,4,18)
Block(6,31,5,18)
Block(6,31,6,18)
Block(6,31,7,18)
Block(6,31,8,18)
Block(6,32,4,18)
Block(6,32,7,18)
Block(6,32,8,18)
Block(6,33,5,18)
Block(6,33,6,18)
Block(6,33,8,18)
Block(6,33,10,18)
Block(6,34,7,18)
Block(6,34,8,18)
Block(6,35,4,18)
Block(6,35,5,18)
Block(6,35,7,18)
Block(6,35,8,18)
Block(6,35,9,18)
Block(6,36,4,18)
Block(6,36,5,18)
Block(6,36,6,18)
Block(6,36,7,18)
Block(6,36,8,18)
Block(6,36,9,18)
Block(6,36,10,18)
Block(6,37,5,18)
Block(6,37,6,18)
Block(6,37,7,18)
Block(6,37,8,18)
Block(6,37,9,18)
Block(6,37,10,18)
Block(6,38,7,18)
Block(6,38,8,18)
Block(6,38,9,18)
Block(6,38,10,18)
Block(6,38,11,18)
Block(6,39,5,18)
Block(6,39,6,18)
Block(6,39,7,18)
Block(6,39,10,18)
Block(6,40,5,18)
Block(6,40,6,18)
Block(6,41,7,18)
Block(7,18,8,18)
Block(7,18,11,18)
Block(7,19,4,18)
Block(7,19,5,18)
Block(7,19,6,18)
Block(7,19,9,18)
Block(7,19,10,18)
Block(7,19,12,18)
Block(7,19,13,18)
Block(7,20,4,18)
Block(7,20,6,18)
Block(7,20,7,18)
Block(7,20,8,18)
Block(7,20,9,18)
Block(7,20,10,18)
Block(7,20,11,18)
Block(7,20,12,18)
Block(7,21,2,18)
Block(7,21,3,18)
Block(7,21,4,18)
Block(7,21,5,18)
Block(7,21,7,18)
Block(7,21,9,18)
Block(7,21,10,18)
Block(7,21,11,18)
Block(7,21,12,18)
Block(7,21,13,18)
Block(7,21,14,18)
Block(7,22,7,18)
Block(7,22,8,18)
Block(7,22,9,18)
Block(7,22,10,18)
Block(7,22,11,18)
Block(7,22,13,18)
Block(7,23,3,18)
Block(7,23,5,18)
Block(7,23,6,18)
Block(7,23,10,18)
Block(7,23,11,18)
Block(7,23,12,18)
Block(7,24,5,18)
Block(7,24,6,18)
Block(7,24,7,18)
Block(7,24,8,18)
Block(7,24,9,18)
Block(7,24,10,18)
Block(7,24,11,18)
Block(7,24,12,18)
Block(7,24,13,18)
Block(7,25,3,18)
Block(7,25,4,18)
Block(7,25,5,18)
Block(7,25,8,18)
Block(7,25,9,18)
Block(7,25,10,18)
Block(7,25,11,18)
Block(7,26,5,18)
Block(7,26,6,18)
Block(7,26,7,18)
Block(7,26,9,18)
Block(7,27,5,18)
Block(7,27,8,18)
Block(7,27,9,18)
Block(7,27,10,18)
Block(7,28,6,18)
Block(7,28,8,18)
Block(7,28,10,18)
Block(7,29,4,18)
Block(7,29,6,18)
Block(7,29,7,18)
Block(7,29,8,18)
Block(7,29,9,18)
Block(7,30,4,18)
Block(7,30,7,18)
Block(7,30,8,18)
Block(7,30,9,18)
Block(7,31,5,18)
Block(7,31,6,18)
Block(7,31,7,18)
Block(7,31,8,18)
Block(7,31,10,18)
Block(7,32,4,18)
Block(7,32,8,18)
Block(7,32,10,18)
Block(7,33,5,18)
Block(7,33,7,18)
Block(7,33,8,18)
Block(7,33,9,18)
Block(7,34,5,18)
Block(7,34,6,18)
Block(7,35,5,18)
Block(7,36,4,18)
Block(7,36,5,18)
Block(7,36,6,18)
Block(7,36,7,18)
Block(7,36,8,18)
Block(7,36,9,18)
Block(7,37,8,18)
Block(7,37,9,18)
Block(7,38,7,18)
Block(7,38,10,18)
Block(8,18,8,18)
Block(8,18,9,18)
Block(8,19,2,18)
Block(8,19,3,18)
Block(8,19,5,18)
Block(8,19,7,18)
Block(8,19,10,18)
Block(8,20,2,18)
Block(8,20,3,18)
Block(8,20,4,18)
Block(8,20,6,18)
Block(8,20,7,18)
Block(8,20,10,18)
Block(8,20,11,18)
Block(8,20,12,18)
Block(8,21,3,18)
Block(8,21,4,18)
Block(8,21,5,18)
Block(8,21,8,18)
Block(8,21,9,18)
Block(8,21,11,18)
Block(8,22,4,18)
Block(8,22,10,18)
Block(8,22,13,18)
Block(8,23,5,18)
Block(8,23,8,18)
Block(8,23,9,18)
Block(8,23,10,18)
Block(8,23,11,18)
Block(8,24,6,18)
Block(8,24,8,18)
Block(8,24,9,18)
Block(8,24,10,18)
Block(8,24,11,18)
Block(8,24,12,18)
Block(8,25,6,18)
Block(8,25,7,18)
Block(8,25,8,18)
Block(8,25,9,18)
Block(8,25,10,18)
Block(8,25,11,18)
Block(8,25,12,18)
Block(8,26,7,18)
Block(8,26,8,18)
Block(8,26,9,18)
Block(8,26,10,18)
Block(8,26,11,18)
Block(8,27,5,18)
Block(8,27,6,18)
Block(8,27,7,18)
Block(8,27,8,18)
Block(8,27,9,18)
Block(8,27,11,18)
Block(8,28,8,18)
Block(8,28,9,18)
Block(8,28,10,18)
Block(8,29,7,18)
Block(8,29,8,18)
Block(8,30,6,18)
Block(8,30,8,18)
Block(8,31,8,18)
Block(8,31,9,18)
Block(8,31,10,18)
Block(8,32,9,18)
Block(8,32,10,18)
Block(8,33,6,18)
Block(8,33,7,18)
Block(8,33,8,18)
Block(8,33,9,18)
Block(8,34,6,18)
Block(8,34,7,18)
Block(8,34,8,18)
Block(8,35,7,18)
Block(8,36,7,18)
Block(9,19,3,18)
Block(9,19,8,18)
Block(9,19,9,18)
Block(9,19,10,18)
Block(9,20,3,18)
Block(9,20,4,18)
Block(9,20,7,18)
Block(9,20,8,18)
Block(9,21,4,18)
Block(9,21,5,18)
Block(9,21,7,18)
Block(9,21,8,18)
Block(9,21,9,18)
Block(9,22,9,18)
Block(9,22,10,18)
Block(9,22,11,18)
Block(9,23,5,18)
Block(9,23,6,18)
Block(9,23,7,18)
Block(9,23,9,18)
Block(9,23,11,18)
Block(9,24,6,18)
Block(9,24,7,18)
Block(9,24,10,18)
Block(9,24,11,18)
Block(9,25,5,18)
Block(9,25,8,18)
Block(9,25,9,18)
Block(9,25,10,18)
Block(9,25,12,18)
Block(9,26,8,18)
Block(9,26,10,18)
Block(9,26,11,18)
Block(9,26,12,18)
Block(9,27,7,18)
Block(9,27,8,18)
Block(9,27,9,18)
Block(9,27,10,18)
Block(9,28,7,18)
Block(9,28,8,18)
Block(9,28,9,18)
Block(9,29,8,18)
Block(9,31,7,18)
Block(9,31,8,18)
Block(10,19,8,18)
Block(10,19,10,18)
Block(10,20,9,18)
Block(10,21,7,18)
Block(10,23,6,18)
Block(10,24,5,18)
Block(10,24,10,18)
Block(10,25,9,18)
Block(10,26,7,18)
Block(10,26,8,18)
Block(10,26,9,18)
Block(10,26,10,18)
Block(10,27,7,18)
Block(10,27,8,18)
Block(10,27,9,18)
Block(10,28,7,18)
Block(10,28,8,18)
Block(11,27,8,18)
Block(11,27,9,18)


#######################################################################
# +-----------------------------------------------------------------+ #
# |                             Entities                            | #
# +-----------------------------------------------------------------+ #
#######################################################################

# Entity() spawns an entity instead of a block. The entity is spawned only once when the BO3 is spawned.
# Entities are persistent by default so they don't de-spawn when no player is near, they are only unloaded.
# Usage: Entity(x,y,z,mobName,groupSize,NameTagOrNBTFileName) or Entity(x,y,z,mobName,groupSize)
# Use /tc entities or /otg entities to get a list of entities that can be used as mobName, this includes entities added by other mods.
# NameTagOrNBTFileName can be either a nametag for the mob or an nbt file (such as mymobinfo.nbt or mymobinfo.txt).
# When using a text file you can use the same mob spawning parameters used with the /summon command to equip the
# entity and give it custom attributes etc. You can copy the DATA part of a summon command including surrounding
# curly braces to a .txt file, for instance for: "/summon Skeleton x y z {DATA}"

#######################################################################
# +-----------------------------------------------------------------+ #
# |                            BO3 checks                           | #
# +-----------------------------------------------------------------+ #
#######################################################################

# Require a condition at a certain location in order for the BO3 to be spawned.
# BlockCheck(x,y,z,BlockName[,BlockName[,...]]) - one of the blocks must be at the location
# BlockCheckNot(x,y,z,BlockName[,BlockName[,...]]) - all the blocks must not be at the location
# LightCheck(x,y,z,minLightLevel,maxLightLevel) - light must be between min and max (inclusive)

# You can use "Solid" as a BlockName for matching all solid blocks or "All" to match all blocks that aren't air.

# Examples:
BlockCheck(0,-1,0,GRASS,DIRT,DIRT:2,SAND,CLAY)
#   BlockCheck(0,-1,0,Solid)       Require any solid block just below the object
#   BlockCheck(0,-1,0,WOOL)        Require any type of wool just below the object
#   BlockCheck(0,-1,0,WOOL:0)      Require white wool just below the object
#   BlockCheckNot(0,-1,0,WOOL:0)   Require that there is no white wool below the object
#   LightCheck(0,0,0,0,1)          Require almost complete darkness just below the object

